<?xml version="1.0" encoding="utf-8"?>
<robot
  name="r2_robotic_arm">
  <link
    name="base_link">
    <inertial>
      <origin
        xyz="-2.12927591876723E-05 5.48031588378215E-06 0.0274260298807097"
        rpy="0 0 0" />
      <mass
        value="1.44975066" />
      <inertia
        ixx="0.00458070"
        ixy="-0.00000043"
        ixz="0.00000019"
        iyy="0.00467596"
        iyz="0.000002949"
        izz="0.00467366" />
    </inertial>
    <visual>
      <origin
        xyz="0 0 0"
        rpy="0 0 0" />
      <geometry>
        <mesh
          filename="package://r2_robotic_arm_description/meshes/base_link.STL" />
      </geometry>
      <material
        name="">
        <color
          rgba="0.752941176470588 0.752941176470588 0.752941176470588 1" />
      </material>
    </visual>
    <collision>
      <origin
        xyz="0 0 0"
        rpy="0 0 0" />
      <geometry>
        <mesh
          filename="package://r2_robotic_arm_description/meshes/base_link.STL" />
      </geometry>
    </collision>
  </link>
  <link
    name="joint_1_link">
    <inertial>
      <origin
        xyz="0.00686250007364108 -6.4217018469813E-05 0.0473286343607914"
        rpy="0 0 0" />
      <mass
        value="1.20681178" />
      <inertia
        ixx="0.00618535"
        ixy="-0.00015190"
        ixz="0.00025404"
        iyy="0.00635680"
        iyz="-0.00044696"
        izz="0.00122037" />
    </inertial>
    <visual>
      <origin
        xyz="0 0 0"
        rpy="0 0 0" />
      <geometry>
        <mesh
          filename="package://r2_robotic_arm_description/meshes/joint_1_link.STL" />
      </geometry>
      <material
        name="">
        <color
          rgba="0.752941176470588 0.752941176470588 0.752941176470588 1" />
      </material>
    </visual>
    <collision>
      <origin
        xyz="0 0 0"
        rpy="0 0 0" />
      <geometry>
        <mesh
          filename="package://r2_robotic_arm_description/meshes/joint_1_link.STL" />
      </geometry>
    </collision>
  </link>
  <joint
    name="joint_1"
    type="revolute">
    <origin
      xyz="0 0 0.058"
      rpy="0 0 0" />
    <parent
      link="base_link" />
    <child
      link="joint_1_link" />
    <axis
      xyz="0 0 -1" />
    <limit
      lower="-5.22"
      upper="0"
      effort="40"
      velocity="100" />
  </joint>
  <link
    name="joint_2_link">
    <inertial>
      <origin
        xyz="0.144347933027611 0.0167926303063024 0.0268734599724394"
        rpy="0 0 0" />
      <mass
        value="1.27038627" />
      <inertia
        ixx="0.00309965"
        ixy="-0.00383893"
        ixz="-0.00500329"
        iyy="0.04379619"
        iyz="-0.00092475"
        izz="0.04444630" />
    </inertial>
    <visual>
      <origin
        xyz="0 0 0"
        rpy="0 0 0" />
      <geometry>
        <mesh
          filename="package://r2_robotic_arm_description/meshes/joint_2_link.STL" />
      </geometry>
      <material
        name="">
        <color
          rgba="0.752941176470588 0.752941176470588 0.752941176470588 1" />
      </material>
    </visual>
    <collision>
      <origin
        xyz="0 0 0"
        rpy="0 0 0" />
      <geometry>
        <mesh
          filename="package://r2_robotic_arm_description/meshes/joint_2_link.STL" />
      </geometry>
    </collision>
  </link>
  <joint
    name="joint_2"
    type="revolute">
    <origin
      xyz="0.032 0 0.08"
      rpy="-1.5708 -0.65642 -1.5708" />
    <parent
      link="joint_1_link" />
    <child
      link="joint_2_link" />
    <axis
      xyz="0 0 1" />
    <limit
      lower="-2.42"
      upper="0"
      effort="40"
      velocity="100" />
  </joint>
  <link
    name="joint_3_link">
    <inertial>
      <origin
        xyz="0.069346694397606 -0.0011487998588938 0.158565752136034"
        rpy="0 0 0" />
      <mass
        value="0.53361407" />
      <inertia
        ixx="0.01965399"
        ixy="0.00007704"
        ixz="-0.00813439"
        iyy="0.02327313"
        iyz="0.00017099"
        izz="0.00427269" />
    </inertial>
    <visual>
      <origin
        xyz="0 0 0"
        rpy="0 0 0" />
      <geometry>
        <mesh
          filename="package://r2_robotic_arm_description/meshes/joint_3_link.STL" />
      </geometry>
      <material
        name="">
        <color
          rgba="0.752941176470588 0.752941176470588 0.752941176470588 1" />
      </material>
    </visual>
    <collision>
      <origin
        xyz="0 0 0"
        rpy="0 0 0" />
      <geometry>
        <mesh
          filename="package://r2_robotic_arm_description/meshes/joint_3_link.STL" />
      </geometry>
    </collision>
  </link>
  <joint
    name="joint_3"
    type="prismatic">
    <origin
      xyz="0.083 0.052 0.0275"
      rpy="-1.5708 0 -1.5708" />
    <parent
      link="joint_2_link" />
    <child
      link="joint_3_link" />
    <axis
      xyz="0 0 -1" />
    <limit
      lower="-0.19"
      upper="0"
      effort="40"
      velocity="100" />
  </joint>
  <link
    name="joint_4_link">
    <inertial>
      <origin
        xyz="0.19903 0.0099575 -0.032036"
        rpy="0 0 0" />
      <mass
        value="0.72989653" />
      <inertia
        ixx="0.00218083"
        ixy="-0.00107276"
        ixz="0.00451925"
        iyy="0.03951902"
        iyz="0.00023957"
        izz="0.03893628" />
    </inertial>
    <visual>
      <origin
        xyz="0 0 0"
        rpy="0 0 0" />
      <geometry>
        <mesh
          filename="package://r2_robotic_arm_description/meshes/joint_4_link.STL" />
      </geometry>
      <material
        name="">
        <color
          rgba="0.86667 0.9098 1 1" />
      </material>
    </visual>
    <collision>
      <origin
        xyz="0 0 0"
        rpy="0 0 0" />
      <geometry>
        <mesh
          filename="package://r2_robotic_arm_description/meshes/joint_4_link.STL" />
      </geometry>
    </collision>
  </link>
  <joint
    name="joint_4"
    type="revolute">
    <origin
      xyz="0.132 -0.033 0.28695"
      rpy="1.5708 1.3614 0" />
    <parent
      link="joint_3_link" />
    <child
      link="joint_4_link" />
    <axis
      xyz="0 0 -1" />
    <limit
      lower="-2.32"
      upper="0"
      effort="40"
      velocity="100" />
  </joint>
  <link
    name="joint_5_link">
    <inertial>
      <origin
        xyz="0.07610913647531 1.94289029309402E-16 -0.038106698009771"
        rpy="0 0 0" />
      <mass
        value="0.18671435" />
      <inertia
        ixx="0.00051868"
        ixy="0.00000000"
        ixz="0.00054001"
        iyy="0.00177976"
        iyz="0.00000000"
        izz="0.00136734" />
    </inertial>
    <visual>
      <origin
        xyz="0 0 0"
        rpy="0 0 0" />
      <geometry>
        <mesh
          filename="package://r2_robotic_arm_description/meshes/joint_5_link.STL" />
      </geometry>
      <material
        name="">
        <color
          rgba="1 1 1 1" />
      </material>
    </visual>
    <collision>
      <origin
        xyz="0 0 0"
        rpy="0 0 0" />
      <geometry>
        <mesh
          filename="package://r2_robotic_arm_description/meshes/joint_5_link.STL" />
      </geometry>
    </collision>
  </link>
  <joint
    name="joint_5"
    type="revolute">
    <origin
      xyz="0.35 0 0.005"
      rpy="0 0 0" />
    <parent
      link="joint_4_link" />
    <child
      link="joint_5_link" />
    <axis
      xyz="0 0 -1" />
    <limit
      lower="-2.4"
      upper="2.4"
      effort="40"
      velocity="100" />
  </joint>
  <link
    name="suction">
    <inertial>
      <origin
        xyz="-0.0237043010356263 1.11022302462516E-16 0"
        rpy="0 0 0" />
      <mass
        value="0.08171729" />
      <inertia
        ixx="0.00007674"
        ixy="0.00000000"
        ixz="0.00000000"
        iyy="0.00009179"
        iyz="0.00000000"
        izz="0.00009179" />
    </inertial>
    <visual>
      <origin
        xyz="0 0 0"
        rpy="0 0 0" />
      <geometry>
        <mesh
          filename="package://r2_robotic_arm_description/meshes/suction.STL" />
      </geometry>
      <material
        name="">
        <color
          rgba="0.298039215686275 0.298039215686275 0.298039215686275 1" />
      </material>
    </visual>
    <collision>
      <origin
        xyz="0 0 0"
        rpy="0 0 0" />
      <geometry>
        <mesh
          filename="package://r2_robotic_arm_description/meshes/suction.STL" />
      </geometry>
    </collision>
  </link>
  <joint
    name="suction"
    type="fixed">
    <origin
      xyz="0.145 0 -0.038"
      rpy="0 0 0" />
    <parent
      link="joint_5_link" />
    <child
      link="suction" />
    <axis
      xyz="0 0 0" />
  </joint>
  <link
    name="camera">
    <inertial>
      <origin
        xyz="-0.00150000000000003 0 0"
        rpy="0 0 0" />
      <mass
        value=" 0.02836985" />
      <inertia
        ixx="0.00002751"
        ixy="0.00000000"
        ixz="0.00000000"
        iyy="0.00000574"
        iyz="0.00000000"
        izz="0.00002193" />
    </inertial>
    <visual>
      <origin
        xyz="0 0 0"
        rpy="0 0 0" />
      <geometry>
        <mesh
          filename="package://r2_robotic_arm_description/meshes/camera.STL" />
      </geometry>
      <material
        name="">
        <color
          rgba="1 1 1 1" />
      </material>
    </visual>
    <collision>
      <origin
        xyz="0 0 0"
        rpy="0 0 0" />
      <geometry>
        <mesh
          filename="package://r2_robotic_arm_description/meshes/camera.STL" />
      </geometry>
    </collision>
  </link>
  <joint
    name="camera"
    type="fixed">
    <origin
      xyz="0.151 0.066936 -0.033"
      rpy="-1.5708 0 0" />
    <parent
      link="joint_4_link" />
    <child
      link="camera" />
    <axis
      xyz="0 0 0" />
  </joint>
</robot>